<?xml version="1.0" ?>
<robot name="kinect" xmlns:xacro="http://ros.org/wiki/xacro">
  
  <link name="base_link">
    <visual>
      <origin xyz="0 0 0" rpy="0 0 0" />
      <geometry>
        <box size="0.075 0.085 0.03" />
      </geometry>
      <material name="black">
        <color rgba="0.05 0.05 0.05 1"/>
      </material>
    </visual>
    <collision>
      <origin xyz="0 0 0" rpy="0 0 0" />
      <geometry>
        <box size="0.075 0.085 0.03" />
      </geometry>
      <material name="black">
        <color rgba="0.05 0.05 0.05 1"/>
      </material>
    </collision>
    <inertial>
      <origin rpy="0 0 0" xyz="0 0 0"/>
      <mass value="0.05"/>
      <inertia ixx="0" ixy="0" ixz="0" iyy="0" iyz="0" izz="0"/>
    </inertial>
  </link>

  <link name="head">
    <visual>
      <origin xyz="0.0 0.0 0.03" rpy="0 0 0" />
      <geometry>
        <box size="0.065 0.28 0.035" />
      </geometry>
      <material name="black">
        <color rgba="0.05 0.05 0.05 1"/>
      </material>
    </visual>
    <collision>
      <origin xyz="0.0 0.0 0.03" rpy="0 0 0" />
      <geometry>
        <box size="0.065 0.28 0.035" />
      </geometry>
      <material name="black">
        <color rgba="0.05 0.05 0.05 1"/>
      </material>
    </collision>
    <inertial>
      <origin rpy="0 0 0" xyz="0 0 0"/>
      <mass value="0.05"/>
      <inertia ixx="0" ixy="0" ixz="0" iyy="0" iyz="0" izz="0"/>
    </inertial>
  </link>

<!-- Joints -->

  <joint name="head_hinge" type="revolute">
    <origin xyz="0.0 0.0 0.005" rpy="0 0 0" />
    <axis xyz="0 1 0" />
    <parent link="base_link" />
    <child link="head" />
    <dynamics damping="0.0" friction="0.5" />
    <limit effort="50" velocity="1" lower="-0.15" upper="0.15" />
  </joint>

</robot>
