<?xml version="1.0" ?>
<!-- =================================================================================== -->
<!-- |    This document was autogenerated by xacro from sda10f.xacro                   | -->
<!-- |    EDITING THIS FILE BY HAND IS NOT RECOMMENDED                                 | -->
<!-- =================================================================================== -->
<robot name="motoman_sda10f" xmlns:xacro="http://ros.org/wiki/xacro">

<!-- motoman base/body links -->
  <link name="base_link">
    <visual>
      <geometry>
        <mesh filename="package://prx_simulation/urdf/meshes/sda10f/visual/motoman_base.stl"/>
      </geometry>
      <material name="blue">
        <color rgba="0 0 1 1"/>
      </material>
    </visual>
    <collision>
      <geometry>
        <mesh filename="package://prx_simulation/urdf/meshes/sda10f/collision/motoman_base.stl"/>
      </geometry>
      <material name="yellow">
        <color rgba="0 1 1 1"/>
      </material>
    </collision>
    <inertial>
      <origin rpy="0 0 0" xyz="0 0 0"/>
      <mass value="0.00094542"/>
      <inertia ixx="2e-08" ixy="0" ixz="0" iyy="3e-08" iyz="0" izz="2e-08"/>
    </inertial>
  </link>
  <link name="torso_link_b1">
    <visual>
      <origin rpy="0 0 0" xyz="0 0 0"/>
      <geometry>
        <mesh filename="package://prx_simulation/urdf/meshes/sda10f/visual/motoman_axis_b1.stl"/>
      </geometry>
      <material name="silver">
        <color rgba="0.8 0.8 0.8 1"/>
      </material>
    </visual>
    <collision>
      <origin rpy="0 0 0" xyz="0 0 0"/>
      <geometry>
        <mesh filename="package://prx_simulation/urdf/meshes/sda10f/collision/motoman_axis_b1.stl"/>
      </geometry>
      <material name="yellow"/>
    </collision>
  </link>
  <link name="torso_link_b2" />

<!-- motoman base/body joints -->
  <joint name="torso_joint_b1" type="revolute">
    <parent link="base_link"/>
    <child link="torso_link_b1"/>
    <origin rpy="0 0 0" xyz="0.09257 0 0.8835"/>
    <axis xyz="0 0 1"/>
    <limit effort="100" lower="-2.9570" upper="2.9570" velocity="2.26"/>
  </joint>
  <joint name="torso_joint_b2" type="revolute">
    <parent link="base_link"/>
    <child link="torso_link_b2"/>
    <origin rpy="0 0 0" xyz="0.09257 0 0.8835"/>
    <axis xyz="0 0 1"/>
    <limit effort="100" lower="-2.9570" upper="2.9570" velocity="2.26"/>
    <mimic joint="torso_joint_b1" multiplier="1" offset="0"/>
  </joint>

<!-- motoman left arm links -->
  <link name="arm_left_link_1_s">
    <visual>
      <origin rpy="0 0 0" xyz="0 0 0"/>
      <geometry>
        <mesh filename="package://prx_simulation/urdf/meshes/sda10f/visual/motoman_axis_s.stl"/>
      </geometry>
      <material name="blue">
        <color rgba="0.8 0.8 0.8 1"/>
      </material>
    </visual>
    <collision>
      <origin rpy="0 0 0" xyz="0 0 0"/>
      <geometry>
        <mesh filename="package://prx_simulation/urdf/meshes/sda10f/collision/motoman_axis_s.stl"/>
      </geometry>
      <material name="yellow"/>
    </collision>
  </link>
  <link name="arm_left_link_2_l">
    <visual>
      <origin rpy="0 0 0" xyz="0 0 0"/>
      <geometry>
        <mesh filename="package://prx_simulation/urdf/meshes/sda10f/visual/motoman_axis_l.stl"/>
      </geometry>
      <material name="silver"/>
    </visual>
    <collision>
      <origin rpy="0 0 0" xyz="0 0 0"/>
      <geometry>
        <mesh filename="package://prx_simulation/urdf/meshes/sda10f/collision/motoman_axis_l.stl"/>
      </geometry>
      <material name="yellow"/>
    </collision>
  </link>
  <link name="arm_left_link_3_e">
    <visual>
      <origin rpy="0 0 0" xyz="0 0 0"/>
      <geometry>
        <mesh filename="package://prx_simulation/urdf/meshes/sda10f/visual/motoman_axis_e.stl"/>
      </geometry>
      <material name="blue"/>
    </visual>
    <collision>
      <origin rpy="0 0 0" xyz="0 0 0"/>
      <geometry>
        <mesh filename="package://prx_simulation/urdf/meshes/sda10f/collision/motoman_axis_e.stl"/>
      </geometry>
      <material name="yellow"/>
    </collision>
  </link>
  <link name="arm_left_link_4_u">
    <visual>
      <origin rpy="0 0 0" xyz="0 0 0"/>
      <geometry>
        <mesh filename="package://prx_simulation/urdf/meshes/sda10f/visual/motoman_axis_u.stl"/>
      </geometry>
      <material name="silver"/>
    </visual>
    <collision>
      <origin rpy="0 0 0" xyz="0 0 0"/>
      <geometry>
        <mesh filename="package://prx_simulation/urdf/meshes/sda10f/collision/motoman_axis_u.stl"/>
      </geometry>
      <material name="yellow"/>
    </collision>
  </link>
  <link name="arm_left_link_5_r">
    <visual>
      <origin rpy="0 0 0" xyz="0 0 0"/>
      <geometry>
        <mesh filename="package://prx_simulation/urdf/meshes/sda10f/visual/motoman_axis_r.stl"/>
      </geometry>
      <material name="blue"/>
    </visual>
    <collision>
      <origin rpy="0 0 0" xyz="0 0 0"/>
      <geometry>
        <mesh filename="package://prx_simulation/urdf/meshes/sda10f/collision/motoman_axis_r.stl"/>
      </geometry>
      <material name="yellow"/>
    </collision>
  </link>
  <link name="arm_left_link_6_b">
    <visual>
      <origin rpy="0 0 0" xyz="0 0 0"/>
      <geometry>
        <mesh filename="package://prx_simulation/urdf/meshes/sda10f/visual/motoman_axis_b.stl"/>
      </geometry>
      <material name="silver"/>
    </visual>
    <collision>
      <origin rpy="0 0 0" xyz="0 0 0"/>
      <geometry>
        <mesh filename="package://prx_simulation/urdf/meshes/sda10f/collision/motoman_axis_b.stl"/>
      </geometry>
      <material name="yellow"/>
    </collision>
  </link>
  <link name="arm_left_link_7_t">
    <visual>
      <geometry>
        <mesh filename="package://prx_simulation/urdf/meshes/sda10f/visual/motoman_axis_t.stl"/>
      </geometry>
      <material name="blue"/>
    </visual>
    <collision>
      <geometry>
        <mesh filename="package://prx_simulation/urdf/meshes/sda10f/collision/motoman_axis_t.stl"/>
      </geometry>
      <material name="yellow"/>
    </collision>
  </link>
  <link name="arm_left_link_tool0"/>

<!-- motoman left arm joints -->
  <joint name="arm_left_joint_1_s" type="revolute">
    <parent link="torso_link_b1"/>
    <child link="arm_left_link_1_s"/>
    <origin rpy="1.57 0 0.0" xyz="0.09996 0.0275 0.32214"/>
    <axis xyz="0 0 -1.0"/>
    <limit effort="0" lower="-3.13" upper="3.13" velocity="2.95"/>
  </joint>
  <joint name="arm_left_joint_2_l" type="revolute">
    <parent link="arm_left_link_1_s"/>
    <child link="arm_left_link_2_l"/>
    <origin rpy="-1.57 0 0" xyz="0 0.0577 -0.2255"/>
    <axis xyz="0 0 -1.0"/>
    <limit effort="0" lower="-1.90" upper="1.90" velocity="2.95"/>
  </joint>
  <joint name="arm_left_joint_3_e" type="revolute">
    <parent link="arm_left_link_2_l"/>
    <child link="arm_left_link_3_e"/>
    <origin rpy="1.57 0 0" xyz="0 0.1690 -0.0454"/>
    <axis xyz="0 0 -1.0"/>
    <limit effort="0" lower="-2.95" upper="2.95" velocity="2.95"/>
  </joint>
  <joint name="arm_left_joint_4_u" type="revolute">
    <parent link="arm_left_link_3_e"/>
    <child link="arm_left_link_4_u"/>
    <origin rpy="-1.57 0 0" xyz="0 -0.0085 -0.181"/>
    <axis xyz="0 0 1"/>
    <limit effort="0" lower="-2.36" upper="2.36" velocity="2.95"/>
  </joint>
  <joint name="arm_left_joint_5_r" type="revolute">
    <parent link="arm_left_link_4_u"/>
    <child link="arm_left_link_5_r"/>
    <origin rpy="1.57 0 0" xyz="0 0.1936 0.0155"/>
    <axis xyz="0 0 1"/>
    <limit effort="0" lower="-3.13" upper="3.13" velocity="3.48"/>
  </joint>
  <joint name="arm_left_joint_6_b" type="revolute">
    <parent link="arm_left_link_5_r"/>
    <child link="arm_left_link_6_b"/>
    <origin rpy="-1.57 0 0" xyz="0 0.0080 -0.155"/>
    <axis xyz="0 0 1"/>
    <limit effort="0" lower="-1.90" upper="1.90" velocity="3.48"/>
  </joint>
  <joint name="arm_left_joint_7_t" type="revolute">
    <parent link="arm_left_link_6_b"/>
    <child link="arm_left_link_7_t"/>
    <origin rpy="1.57 0 0" xyz="0 0.168 -0.015"/>
    <axis xyz="0 0 -1.0"/>
    <limit effort="0" lower="-3.13" upper="3.13" velocity="6.97"/>
  </joint>
  <joint name="arm_left_joint_tool0" type="fixed">
    <origin rpy="0 0 -3.13" xyz="0 0 -0.05"/>
    <parent link="arm_left_link_7_t"/>
    <child link="arm_left_link_tool0"/>
  </joint>

<!-- reflex hand  -->

<!-- ################ ################ ################ ################ ################ ################ -->
<!-- ################ THE SECTION CREATED BY SOLIDWORKS EXPORTER, CUT AND PASTE THIS IN HERE ################ -->
<!-- ################ YOU CAN ALTER THE COLORS FROM HERE ################ -->
<!-- ################ COMMENT OUT ALL dist*_joint PIECES OF THIS URDF SO THE FLEX JOINTS CAN LINK UP ################ -->
<!-- ################ ################ ################ ################ ################ ################ -->
  <link name="reflex_palm">
    <visual>
      <origin   xyz="0 0 0"
        rpy="0 0 0" />
      <geometry>
        <mesh filename="package://reflex_visualizer/meshes/base_link.STL" />
      </geometry>
      <material name="reflex_palm_color">
        <color rgba="1.0 0.55 0.0 1"/>
      </material>
    </visual>
  </link>
  <link name="reflex_palm_pad">
    <visual>
      <origin   xyz="0 0 0"
        rpy="0 0 0" />
      <geometry>
        <mesh filename="package://reflex_visualizer/meshes/pad.STL" />
      </geometry>
      <material name="reflex_palm_pad_color">
        <color rgba="1.0 0.0 0.0 1"/>
      </material>
    </visual>
  </link>
  <joint name="reflex_pad_joint" type="fixed">
    <origin xyz="0.02 0 0.063"
      rpy="1.5707963267949 5.55111512312578E-17 -1.5707963267949" />
    <parent link="reflex_palm" />
    <child link="reflex_palm_pad" />
    <axis xyz="0 0 0" />
  </joint>
  <link name="reflex_swivel_1">
    <visual>
      <origin   xyz="0 0 0"
        rpy="0 0 0" />
      <geometry>
        <mesh filename="package://reflex_visualizer/meshes/swivel_1.STL" />
      </geometry>
      <material name="reflex_swivel_color">
        <color rgba="1.0 0.55 0.0 1"/>
      </material>
    </visual>
  </link>
  <joint name="reflex_preshape_1" type="revolute">
    <origin xyz="0.0503973683071414 -0.026 0.063"
      rpy="6.75550818663469E-16 1.97993848419069E-16 -2.77555756156289E-16" />
    <parent link="reflex_palm" />
    <child link="reflex_swivel_1" />
    <axis xyz="0 0 -1" />
    <limit effort="100" lower="0" upper="1.57" velocity="100"/>
  </joint>
  <link name="reflex_proximal_1">
    <visual>
      <origin   xyz="0 0 0"
        rpy="0 0 0" />
      <geometry>
        <mesh filename="package://reflex_visualizer/meshes/proximal_1.STL" />
      </geometry>
      <material name="reflex_proximal_color">
        <color rgba="1.0 0.55 0.0 1"/>
      </material>
    </visual>
  </link>
  <joint name="reflex_proximal_joint_1" type="revolute">
    <origin xyz="0.01 0 0.0186"
      rpy="-6.20039667432211E-16 2.40507565059625E-17 2.22044604925031E-16" />
    <parent link="reflex_swivel_1" />
    <child link="reflex_proximal_1" />
    <axis xyz="0 -1 0" />
    <limit effort="100" lower="0" upper="2.88" velocity="100"/>
  </joint>
  <link name="reflex_proximal_pad_1">
    <visual>
      <origin   xyz="0 0 0"
        rpy="0 0 0" />
      <geometry>
        <mesh filename="package://reflex_visualizer/meshes/proximal_pad_1.STL" />
      </geometry>
      <material name="reflex_pad_red">
        <color rgba="1.0 0.0 0.0 1"/>
      </material>
    </visual>
  </link>
  <joint name="reflex_prox1_pad_joint" type="fixed">
    <origin xyz="0 0 0"
      rpy="1.5707963267949 0 -1.5707963267949" />
    <parent link="reflex_proximal_1" />
    <child link="reflex_proximal_pad_1" />
    <axis xyz="0 0 0" />
  </joint>
  <link name="reflex_distal_1">
    <visual>
      <origin   xyz="0.01 0 -0.004"
        rpy="0 0 0" />
      <geometry>
        <mesh filename="package://reflex_visualizer/meshes/distal_1.STL" />
      </geometry>
      <material name="reflex_distal_color">
        <color rgba="1.0 0.55 0.0 1"/>
      </material>
    </visual>
  </link>
  <joint name="reflex_distal_joint_1" type="revolute">
    <origin xyz="0.0760000000000001 0 0.00250000000000002"
      rpy="0 0 0" />
    <parent link="reflex_proximal_1" />
    <child link="reflex_distal_1" />
    <axis xyz="0 -1 0" />
    <limit effort="100" lower="0" upper="2.27" velocity="100"/>
  </joint>
  <link name="reflex_distal_pad_1">
    <visual>
      <origin   xyz="0 -0.004 -0.01"
        rpy="0 0 0" />
      <geometry>
        <mesh filename="package://reflex_visualizer/meshes/distal_pad_1.STL" />
      </geometry>
      <material name="reflex_pad_red">
        <color rgba="1.0 0.0 0.0 1"/>
      </material>
    </visual>
  </link>
  <joint name="reflex_dist1_pad_joint" type="fixed">
    <origin xyz="-0.0760000000000001 0 -0.0025"
      rpy="1.5707963267949 0 -1.5707963267949" />
    <parent link="reflex_distal_1" />
    <child link="reflex_distal_pad_1" />
    <axis xyz="0 0 0" />
  </joint>
  <link name="reflex_swivel_2">
    <visual>
      <origin   xyz="0 0 0"
        rpy="0 0 0" />
      <geometry>
        <mesh filename="package://reflex_visualizer/meshes/swivel_2.STL" />
      </geometry>
      <material name="reflex_swivel_color">
        <color rgba="1.0 0.55 0.0 1"/>
      </material>
    </visual>
  </link>
  <joint name="reflex_preshape_2" type="revolute">
    <origin xyz="0.0503973683071413 0.0259999999999999 0.063"
      rpy="1.22459340959228E-15 -7.33448407631817E-16 -1.66533453693773E-16" />
    <parent link="reflex_palm" />
    <child link="reflex_swivel_2" />
    <axis xyz="0 0 -1" />
    <limit effort="100" lower="-1.57" upper="0" velocity="100"/>
  </joint>
  <link name="reflex_proximal_2">
    <visual>
      <origin   xyz="0 0 0"
        rpy="0 0 0" />
      <geometry>
        <mesh filename="package://reflex_visualizer/meshes/proximal_2.STL" />
      </geometry>
      <material name="reflex_proximal_color">
        <color rgba="1.0 0.55 0.0 1"/>
      </material>
    </visual>
  </link>
  <joint name="reflex_proximal_joint_2" type="revolute">
    <origin xyz="0.01 0 0.0186"
      rpy="-1.16908225836102E-15 9.55493012556849E-16 1.11022302462515E-16" />
    <parent link="reflex_swivel_2" />
    <child link="reflex_proximal_2" />
    <axis xyz="0 -1 0" />
    <limit effort="100" lower="0" upper="2.88" velocity="100"/>
  </joint>
  <link name="reflex_proximal_pad_2">
    <visual>
      <origin   xyz="0 0 0"
        rpy="0 0 0" />
      <geometry>
        <mesh filename="package://reflex_visualizer/meshes/proximal_pad_2.STL" />
      </geometry>
      <material name="reflex_pad_red">
        <color rgba="1.0 0.0 0.0 1"/>
      </material>
    </visual>
  </link>
  <joint name="reflex_prox2_pad_joint" type="fixed">
    <origin xyz="0 0 0"
      rpy="1.5707963267949 0 -1.5707963267949" />
    <parent link="reflex_proximal_2" />
    <child link="reflex_proximal_pad_2" />
    <axis xyz="0 0 0" />
  </joint>
  <link name="reflex_distal_2">
    <visual>
      <origin   xyz="0.01 0 -0.004"
        rpy="0 0 0" />
      <geometry>
        <mesh filename="package://reflex_visualizer/meshes/distal_2.STL" />
      </geometry>
      <material name="reflex_distal_color">
        <color rgba="1.0 0.55 0.0 1"/>
      </material>
    </visual>
  </link>
  <joint name="reflex_distal_joint_2" type="revolute">
    <origin xyz="0.0760000000000001 0 0.00249999999999997"
      rpy="0 0 0" />
    <parent link="reflex_proximal_2" />
    <child link="reflex_distal_2" />
    <axis xyz="0 -1 0" />
    <limit effort="100" lower="0" upper="2.27" velocity="100"/>
  </joint>
  <link name="reflex_distal_pad_2">
    <visual>
      <origin   xyz="0 -0.004 -0.01"
        rpy="0 0 0" />
      <geometry>
        <mesh filename="package://reflex_visualizer/meshes/distal_pad_2.STL" />
      </geometry>
      <material name="reflex_pad_red">
        <color rgba="1.0 0.0 0.0 1"/>
      </material>
    </visual>
  </link>
  <joint name="reflex_dist2_pad_joint" type="fixed">
    <origin xyz="-0.0760000000000001 0 -0.0025"
      rpy="1.5707963267949 0 -1.5707963267949" />
    <parent link="reflex_distal_2" />
    <child link="reflex_distal_pad_2" />
    <axis xyz="0 0 0" />
  </joint>
  <link name="reflex_proximal_3">
    <visual>
      <origin   xyz="0 0 0"
        rpy="0 0 0" />
      <geometry>
        <mesh filename="package://reflex_visualizer/meshes/proximal_3.STL" />
      </geometry>
      <material name="reflex_proximal_color">
        <color rgba="1.0 0.55 0.0 1"/>
      </material>
    </visual>
  </link>
  <joint name="reflex_proximal_joint_3" type="revolute">
    <origin xyz="-0.0299999999999996 0 0.0816000000000002"
      rpy="-5.55111512312578E-17 -2.22044604925031E-16 3.14159265358979" />
    <parent link="reflex_palm" />
    <child link="reflex_proximal_3" />
    <axis xyz="0 -1 0" />
    <limit effort="100" lower="0" upper="2.88" velocity="100"/>
  </joint>
  <link name="reflex_proximal_pad_3">
    <visual>
      <origin   xyz="0 0 0"
        rpy="0 0 0" />
      <geometry>
        <mesh filename="package://reflex_visualizer/meshes/proximal_pad_3.STL" />
      </geometry>
      <material name="reflex_pad_red">
        <color rgba="1.0 0.0 0.0 1"/>
      </material>
    </visual>
  </link>
  <joint name="reflex_prox3_pad_joint" type="fixed">
    <origin xyz="0 0 0"
      rpy="1.5707963267949 1.22460635382238E-16 -1.5707963267949" />
    <parent link="reflex_proximal_3" />
    <child link="reflex_proximal_pad_3" />
    <axis xyz="0 0 0" />
  </joint>
  <link name="reflex_distal_3">
    <visual>
      <origin   xyz="0.01 0 -0.004"
        rpy="0 0 0" />
      <geometry>
        <mesh filename="package://reflex_visualizer/meshes/distal_3.STL" />
      </geometry>
      <material name="reflex_distal_color">
        <color rgba="1.0 0.55 0.0 1"/>
      </material>
    </visual>
  </link>
  <joint name="reflex_distal_joint_3" type="revolute">
    <origin xyz="0.0760000000000001 0 0.0025"
      rpy="-1.48887961834512E-45 -1.0995850059156E-76 -7.38531841236285E-32" />
    <parent link="reflex_proximal_3" />
    <child link="reflex_distal_3" />
    <axis xyz="0 -1 0" />
    <limit effort="100" lower="0" upper="2.27" velocity="100"/>
  </joint>
  <link name="reflex_distal_pad_3">
    <visual>
      <origin   xyz="0 -0.004 -0.01"
        rpy="0 0 0" />
      <geometry>
        <mesh filename="package://reflex_visualizer/meshes/distal_pad_3.STL" />
      </geometry>
      <material name="reflex_pad_red">
        <color rgba="1.0 0.0 0.0 1"/>
      </material>
    </visual>
  </link>
  <joint name="reflex_dist3_pad_joint" type="fixed">
    <origin xyz="-0.0760000000000001 0 -0.0025"
      rpy="1.5707963267949 -1.22460635382238E-16 -1.5707963267949" />
    <parent link="reflex_distal_3" />
    <child link="reflex_distal_pad_3" />
    <axis xyz="0 0 0" />
  </joint>


<!-- right arm links -->
  <link name="arm_right_link_1_s">
    <visual>
      <origin rpy="0 0 0" xyz="0 0 0"/>
      <geometry>
        <mesh filename="package://prx_simulation/urdf/meshes/sda10f/visual/motoman_axis_s.stl"/>
      </geometry>
      <material name="blue">
        <color rgba="0.8 0.8 0.8 1"/>
      </material>
    </visual>
    <collision>
      <origin rpy="0 0 0" xyz="0 0 0"/>
      <geometry>
        <mesh filename="package://prx_simulation/urdf/meshes/sda10f/collision/motoman_axis_s.stl"/>
      </geometry>
      <material name="yellow"/>
    </collision>
  </link>
  <link name="arm_right_link_2_l">
    <visual>
      <origin rpy="0 0 0" xyz="0 0 0"/>
      <geometry>
        <mesh filename="package://prx_simulation/urdf/meshes/sda10f/visual/motoman_axis_l.stl"/>
      </geometry>
      <material name="silver"/>
    </visual>
    <collision>
      <origin rpy="0 0 0" xyz="0 0 0"/>
      <geometry>
        <mesh filename="package://prx_simulation/urdf/meshes/sda10f/collision/motoman_axis_l.stl"/>
      </geometry>
      <material name="yellow"/>
    </collision>
  </link>
  <link name="arm_right_link_3_e">
    <visual>
      <origin rpy="0 0 0" xyz="0 0 0"/>
      <geometry>
        <mesh filename="package://prx_simulation/urdf/meshes/sda10f/visual/motoman_axis_e.stl"/>
      </geometry>
      <material name="blue"/>
    </visual>
    <collision>
      <origin rpy="0 0 0" xyz="0 0 0"/>
      <geometry>
        <mesh filename="package://prx_simulation/urdf/meshes/sda10f/collision/motoman_axis_e.stl"/>
      </geometry>
      <material name="yellow"/>
    </collision>
  </link>
  <link name="arm_right_link_4_u">
    <visual>
      <origin rpy="0 0 0" xyz="0 0 0"/>
      <geometry>
        <mesh filename="package://prx_simulation/urdf/meshes/sda10f/visual/motoman_axis_u.stl"/>
      </geometry>
      <material name="silver"/>
    </visual>
    <collision>
      <origin rpy="0 0 0" xyz="0 0 0"/>
      <geometry>
        <mesh filename="package://prx_simulation/urdf/meshes/sda10f/collision/motoman_axis_u.stl"/>
      </geometry>
      <material name="yellow"/>
    </collision>
  </link>
  <link name="arm_right_link_5_r">
    <visual>
      <origin rpy="0 0 0" xyz="0 0 0"/>
      <geometry>
        <mesh filename="package://prx_simulation/urdf/meshes/sda10f/visual/motoman_axis_r.stl"/>
      </geometry>
      <material name="blue"/>
    </visual>
    <collision>
      <origin rpy="0 0 0" xyz="0 0 0"/>
      <geometry>
        <mesh filename="package://prx_simulation/urdf/meshes/sda10f/collision/motoman_axis_r.stl"/>
      </geometry>
      <material name="yellow"/>
    </collision>
  </link>
  <link name="arm_right_link_6_b">
    <visual>
      <origin rpy="0 0 0" xyz="0 0 0"/>
      <geometry>
        <mesh filename="package://prx_simulation/urdf/meshes/sda10f/visual/motoman_axis_b.stl"/>
      </geometry>
      <material name="silver"/>
    </visual>
    <collision>
      <origin rpy="0 0 0" xyz="0 0 0"/>
      <geometry>
        <mesh filename="package://prx_simulation/urdf/meshes/sda10f/collision/motoman_axis_b.stl"/>
      </geometry>
      <material name="yellow"/>
    </collision>
  </link>
  <link name="arm_right_link_7_t">
    <visual>
      <geometry>
        <mesh filename="package://prx_simulation/urdf/meshes/sda10f/visual/motoman_axis_t.stl"/>
      </geometry>
      <material name="blue"/>
    </visual>
    <collision>
      <geometry>
        <mesh filename="package://prx_simulation/urdf/meshes/sda10f/collision/motoman_axis_t.stl"/>
      </geometry>
      <material name="yellow"/>
    </collision>
  </link>
  <link name="arm_right_link_tool0"/>
  <!--
  <link name="sensor_right" >
    <visual>
      <geometry>
        <box size="0.1 0.05 0.03" />
      </geometry>
      <material name="red"/>
    </visual>
  </link>
  <joint name="sensor_right_joint" type="fixed">
    <parent link="arm_right_link_6_b"/>
    <child link="sensor_right"/>
    <origin rpy="0 0 0" xyz="0.0 0.0 .1"/>
  </joint>
  -->

<!-- right arm joints -->
  <joint name="arm_right_joint_1_s" type="revolute">
    <parent link="torso_link_b1"/>
    <child link="arm_right_link_1_s"/>
    <origin rpy="1.57 0 -3.14" xyz="0.09996 -0.0275 0.32214"/>
    <axis xyz="0 0 1.0"/>
    <limit effort="0" lower="-3.13" upper="3.13" velocity="2.95"/>
  </joint>
  <joint name="arm_right_joint_2_l" type="revolute">
    <parent link="arm_right_link_1_s"/>
    <child link="arm_right_link_2_l"/>
    <origin rpy="-1.57 0 0" xyz="0 0.0577 -0.2255"/>
    <axis xyz="0 0 1.0"/>
    <limit effort="0" lower="-1.90" upper="1.90" velocity="2.95"/>
  </joint>
  <joint name="arm_right_joint_3_e" type="revolute">
    <parent link="arm_right_link_2_l"/>
    <child link="arm_right_link_3_e"/>
    <origin rpy="1.57 0 0" xyz="0 0.1690 -0.0454"/>
    <axis xyz="0 0 1.0"/>
    <limit effort="0" lower="-2.95" upper="2.95" velocity="2.95"/>
  </joint>
  <joint name="arm_right_joint_4_u" type="revolute">
    <parent link="arm_right_link_3_e"/>
    <child link="arm_right_link_4_u"/>
    <origin rpy="-1.57 0 0" xyz="0 -0.0085 -0.181"/>
    <axis xyz="0 0 -1"/>
    <limit effort="0" lower="-2.36" upper="2.36" velocity="2.95"/>
  </joint>
  <joint name="arm_right_joint_5_r" type="revolute">
    <parent link="arm_right_link_4_u"/>
    <child link="arm_right_link_5_r"/>
    <origin rpy="1.57 0 0" xyz="0 0.1936 0.0155"/>
    <axis xyz="0 0 -1"/>
    <limit effort="0" lower="-3.13" upper="3.13" velocity="3.48"/>
  </joint>
  <joint name="arm_right_joint_6_b" type="revolute">
    <parent link="arm_right_link_5_r"/>
    <child link="arm_right_link_6_b"/>
    <origin rpy="-1.57 0 0" xyz="0 0.0080 -0.155"/>
    <axis xyz="0 0 -1"/>
    <limit effort="0" lower="-1.90" upper="1.90" velocity="3.48"/>
  </joint>
  <joint name="arm_right_joint_7_t" type="revolute">
    <parent link="arm_right_link_6_b"/>
    <child link="arm_right_link_7_t"/>
    <origin rpy="1.57 0 0" xyz="0 0.168 -0.015"/>
    <axis xyz="0 0 1.0"/>
    <limit effort="0" lower="-3.13" upper="3.13" velocity="6.97"/>
  </joint>
  <joint name="arm_right_joint_tool0" type="fixed">
    <origin rpy="0 0 -3.13" xyz="0 0 0.0"/>
    <parent link="arm_right_link_7_t"/>
    <child link="arm_right_link_tool0"/>
  </joint>
  <joint name="reflex_hand" type="fixed">
    <origin rpy="3.14 0 0" xyz="0 0 0.0"/>
    <parent link="arm_right_link_tool0"/>
    <child link="reflex_palm"/>
  </joint>

  <xacro:motoman_sda10f prefix=""/>
</robot>

