<?xml version="1.0" ?>
<robot xmlns:xacro="http://ros.org/wiki/xacro">
  <xacro:macro name="unigripper" params="prefix">

    <link name="${prefix}base_plate">
      <visual>
        <geometry>
          <cylinder radius="0.04" length="0.008" />
        </geometry>
        <material name="silver">
          <color rgba="0.76 0.76 0.82 1"/>
        </material>
      </visual>
      <collision>
        <origin xyz="0 0 0" rpy="0 0 0" />
        <geometry>
          <cylinder radius="0.04" length="0.008" />
        </geometry>
        <material name="silver">
          <color rgba="0.76 0.76 0.82 1"/>
        </material>
      </collision>
      <inertial>
        <origin rpy="0 0 0" xyz="0 0 0"/>
        <mass value="0.002"/>
        <inertia ixx="0" ixy="0" ixz="0" iyy="0" iyz="0" izz="0"/>
      </inertial>
    </link>
    
    <link name="${prefix}main_beam">
      <visual>
        <geometry>
          <box size="0.015 0.040 0.180" />
        </geometry>
        <material name="silver">
          <color rgba="0.76 0.76 0.82 1"/>
        </material>
      </visual>
      <collision>
        <origin xyz="0 0 0.0" rpy="0 0 0" />
        <geometry>
          <box size="0.015 0.040 0.180" />
        </geometry>
        <material name="silver">
          <color rgba="0.76 0.76 0.82 1"/>
        </material>
      </collision>
      <inertial>
        <origin rpy="0 0 0" xyz="0 0 0"/>
        <mass value="0.01"/>
        <inertia ixx="0" ixy="0" ixz="0" iyy="0" iyz="0" izz="0"/>
      </inertial>
    </link>
    
    <link name="${prefix}actuator">
      <visual>
        <geometry>
          <box size="0.03 0.035 0.180" />
        </geometry>
        <material name="dark_grey">
          <color rgba="0.2 0.2 0.2 1"/>
        </material>
      </visual>
      <collision>
        <origin xyz="0 0 0.0" rpy="0 0 0" />
        <geometry>
          <box size="0.03 0.035 0.180" />
        </geometry>
        <material name="dark_grey">
          <color rgba="0.2 0.2 0.2 1"/>
        </material>
      </collision>
      <inertial>
        <origin rpy="0 0 0" xyz="0 0 0"/>
        <mass value="0.01"/>
        <inertia ixx="0" ixy="0" ixz="0" iyy="0" iyz="0" izz="0"/>
      </inertial>
    </link>
    
    <link name="${prefix}head_connector">
      <visual>
        <origin xyz="-0.01 0.0 -0.004" rpy="0 0 0" />
        <geometry>
          <box size="0.035 0.015 0.039" />
        </geometry>
        <material name="silver">
          <color rgba="0.76 0.76 0.82 1"/>
        </material>
      </visual>
      <collision>
        <origin xyz="-0.01 0.0 -0.004" rpy="0 0 0" />
        <geometry>
          <box size="0.035 0.015 0.039" />
        </geometry>
        <material name="silver">
          <color rgba="0.76 0.76 0.82 1"/>
        </material>
      </collision>
      <inertial>
        <origin rpy="0 0 0" xyz="0 0 0"/>
        <mass value="0.01"/>
        <inertia ixx="0" ixy="0" ixz="0" iyy="0" iyz="0" izz="0"/>
      </inertial>
    </link>
    
    <link name="${prefix}head_plate">
      <visual>
        <origin xyz="-0.01 0.0 -0.004" rpy="0 0 0" />
        <geometry>
          <box size="0.045 0.045 0.005" />
        </geometry>
        <material name="silver">
          <color rgba="0.76 0.76 0.82 1"/>
        </material>
      </visual>
      <collision>
        <origin xyz="-0.01 0.0 -0.004" rpy="0 0 0" />
        <geometry>
          <box size="0.045 0.045 0.005" />
        </geometry>
        <material name="silver">
          <color rgba="0.76 0.76 0.82 1"/>
        </material>
      </collision>
      <inertial>
        <origin rpy="0 0 0" xyz="0 0 0"/>
        <mass value="0.01"/>
        <inertia ixx="0" ixy="0" ixz="0" iyy="0" iyz="0" izz="0"/>
      </inertial>
    </link>
    
    <link name="${prefix}head_base">
      <visual>
        <origin xyz="-0.01 0.0 -0.004" rpy="0 0 0" />
        <geometry>
          <box size="0.062 0.121 0.038" />
        </geometry>
        <material name="silver">
          <color rgba="0.76 0.76 0.82 1"/>
        </material>
      </visual>
      <collision>
        <origin xyz="-0.01 0.0 -0.004" rpy="0 0 0" />
        <geometry>
          <box size="0.062 0.121 0.03" />
        </geometry>
        <material name="silver">
          <color rgba="0.76 0.76 0.82 1"/>
        </material>
      </collision>
      <inertial>
        <origin rpy="0 0 0" xyz="0 0 0"/>
        <mass value="0.01"/>
        <inertia ixx="0" ixy="0" ixz="0" iyy="0" iyz="0" izz="0"/>
      </inertial>
    </link>
    
    <link name="${prefix}head_sponge">
      <visual>
        <origin xyz="-0.01 0.0 -0.004" rpy="0 0 0" />
        <geometry>
          <box size="0.06 0.12 0.008" />
        </geometry>
        <material name="black">
          <color rgba="0 0 0 1"/>
        </material>
      </visual>
      <collision>
        <origin xyz="-0.01 0.0 -0.004" rpy="0 0 0" />
        <geometry>
          <box size="0.06 0.12 0.016" />
        </geometry>
        <material name="black">
          <color rgba="0.2 0.2 0.2 1"/>
        </material>
      </collision>
      <inertial>
        <origin rpy="0 0 0" xyz="0 0 0"/>
        <mass value="0.01"/>
        <inertia ixx="0" ixy="0" ixz="0" iyy="0" iyz="0" izz="0"/>
      </inertial>
    </link>

    <link name="${prefix}tube_port">
      <visual>
        <origin xyz="-0.01 0.0 -0.004" rpy="0 0 0" />
        <geometry>
          <cylinder radius="0.01" length="0.025" />
        </geometry>
        <material name="blue">
          <color rgba="0.1 0.1 0.92 1"/>
        </material>
      </visual>
      <collision>
        <origin xyz="-0.01 0.0 -0.004" rpy="0 0 0" />
        <geometry>
          <cylinder radius="0.01" length="0.025" />
        </geometry>
        <material name="blue">
          <color rgba="0.1 0.1 0.92 1"/>
        </material>
      </collision>
      <inertial>
        <origin rpy="0 0 0" xyz="0 0 0"/>
        <mass value="0.01"/>
        <inertia ixx="0" ixy="0" ixz="0" iyy="0" iyz="0" izz="0"/>
      </inertial>
    </link>
    

    <!-- Joints -->

    <joint name="${prefix}plate_beam" type="fixed">
      <origin xyz="0.0 0.0 0.094" rpy="0 0 0" />
      <axis xyz="0 0 0" />
      <parent link="${prefix}base_plate" />
      <child link="${prefix}main_beam" />
    </joint>

    <joint name="${prefix}beam_act" type="fixed">
      <origin xyz="-0.0225 0.0 0.0" rpy="0 0 0" />
      <axis xyz="0 0 0" />
      <parent link="${prefix}main_beam" />
      <child link="${prefix}actuator" />
    </joint>

    <joint name="${prefix}neck_plate" type="fixed">
      <origin xyz="0.0 0 0.022" rpy="0 0 0" />
      <axis xyz="0 0 0" />
      <parent link="${prefix}head_connector" />
      <child link="${prefix}head_plate" />
    </joint>

    <joint name="${prefix}plate_head" type="fixed">
      <origin xyz="0.0 0 0.0215" rpy="0 0 0" />
      <axis xyz="0 0 0" />
      <parent link="${prefix}head_plate" />
      <child link="${prefix}head_base" />
    </joint>

    <joint name="${prefix}head_sponge" type="fixed">
      <origin xyz="0.0 0 0.023" rpy="0 0 0" />
      <axis xyz="0 0 0" />
      <parent link="${prefix}head_base" />
      <child link="${prefix}head_sponge" />
    </joint>

    <joint name="${prefix}head_valve" type="fixed">
      <origin xyz="0.0 0.0435 -0.0275" rpy="0 0 0" />
      <axis xyz="0 0 0" />
      <parent link="${prefix}head_base" />
      <child link="${prefix}tube_port" />
    </joint>

    <joint name="${prefix}head_hinge" type="revolute">
      <origin xyz="0.0 0.0 0.0825" rpy="0 0 0" />
      <axis xyz="0 1 0" />
      <parent link="${prefix}main_beam" />
      <child link="${prefix}head_connector" />
      <dynamics damping="0.0" friction="0.5" />
      <limit effort="50" velocity="0.2" lower="0.0" upper="1.57" />
    </joint>

  </xacro:macro>
</robot>
